Workbook

Sheet PROGRAMA LECTURA
B3: DIALOGO DIARIA DE SEGURIDAD | AD3: CÓDIGO:
AD5: REVISIÓN:
B7: AVANCE CAPACITACIONES ANEXO 6 - 2026 | AW7: %
A9: DIAS DEL MES | B9: 46174 | C9: =B9+1 -> 46175 | D9: =C9+1 -> 46176 | E9: =D9+1 -> 46177 | F9: =E9+1 -> 46178 | G9: =F9+1 -> 46179 | H9: =G9+1 -> 46180 | I9: =H9+1 -> 46181 | J9: =I9+1 -> 46182 | ... U9: =T9+1 -> 46193 | V9: ENERO | X9: FEBRERO | Z9: MARZO | AB9: ABRIL | AE9: MAYO | AG9: JUNIO | AJ9: JULIO | AM9: AGOSTO | AP9: SETIEMBRE | AR9: OCTUBRE | AT9: NOVIEMBRE | AV9: DICIEMBRE
A10: TEMAS | B10: TIPOS DE SOSTENIMIENTO | C10: IPERC | D10: INSPECCIONES DE EQUIPOS BAJO PERFIL | E10: RESPUESTAS A EMERGENCIAS POR AREAS ESPECIFICIAS | F10: DIA MUNDIAL DEL MEDIO AMBIENTE | G10: IMPORTANCIA DEL USO DE GUARDAS DE SEGURIDAD EN EQUIPOS DE ROTACION | H10: RESPONSABILIDAD AMBIENTAL | I10: PERFORACION Y VOLADRUA | J10: IPERC | K10: USO DE EQUIPO DE PODER | L10: PRIMEROS AUXILIOS | M10: MANEJO DE TRASPORTE DE EXPLOSIVOS | N10: USO DE ESCALERAS | O10: USO RACIOANL DE ENERGIA | P10: VENTILACION DE LABORES | Q10: CONTROL DE SUSTANCIAS PELIGROSAS | R10: HERRAMIENTAS MANUALES | S10: DESCANOS MEDICOS | T10: HOJAS MSDS | U10: PELIGRO DE PUNTOS CIEGOS | V10: Respuesta a Emergencias por Áreas específicas. | W10: Primeros Auxilios | X10: Notificación, investigación y reporte de incidentes , incidentes peligrosos y accidentes de trabajo. | Y10: IPERC | Z10: Trabajos en Altura | AA10: Prevención y Protección Contra Incendio | AB10: Gestión de la Seguridad y Salud Ocupacional basado en el Reglamento de Seguridad y Salud Ocupacional, Política de Seguridad, Salud Ocupacional y Medio Ambiente. | AC10: Mapa de riesgos | AD10: Estándares y procedimiento escrito de trabajo seguro por actividades | AE10: Significado y uso de código de señales y colores. | AF10: Auditoría, fiscalización e Inspecciones de Seguridad | AG10: IPERC | AH10: Higiene Ocupacional (Agentes Físicos, Químicos y Biológicos) Disposición de residuos sólidos. Control de Sustancias peligrosas. | AI10: Manejo defensivo y/o transporte de personal | AJ10: Respuesta a Emergencias por Áreas específicas. | AK10: Comité de Seguridad y Salud Ocupacional. Reglamento Interno de Seguridad y Salud Ocupaciona. Programa Anual de Seguridad y Salud Ocupacional. | AL10: Seguridad en la Oficina y Ergonomía. | AM10: Riesgos Psicosociales | AN10: Riesgos Eléctricos | AO10: Prevención de accidente por desprendimiento de rocas | AP10: Prevención de accidente por gaseamiento | AQ10: Uso de Equipo de Protección Personal (EPP) | AR10: IPERC | AS10: Prevención y Protección Contra Incendio | AT10: Liderazgo y motivación: Seguridad basada en el Comportamiento. | AU10: Primeros Auxilios | AV10: Respuesta a Emergencias por Áreas específicas.
A11: MINA CANDELARIA | U11: P | V11: C | W11: C | X11: C | Y11: C | Z11: C | AA11: C | AB11: C | AC11: C | AD11: C | AE11: C | AF11: C | AG11: C | AH11: C | AI11: F | AJ11: C | AK11: F | AL11: EP | AW11: =IFERROR(COUNTIF(V11:AV11,"C")/COUNTA(V11:AV11),0) -> 0.82352941
A12: PLANTA MAHUARA | U12: P | V12: C | W12: C | X12: C | Y12: C | Z12: C | AA12: C | AB12: C | AC12: C | AD12: C | AE12: C | AF12: C | AG12: C | AH12: C | AI12: F | AJ12: C | AK12: F | AL12: EP | AW12: =IFERROR(COUNTIF(V12:AV12,"C")/COUNTA(V12:AV12),0) -> 0.82352941
A13: ADMINISTRACIÓN | U13: P | V13: C | W13: C | X13: C | Y13: C | Z13: C | AA13: C | AB13: C | AC13: C | AD13: C | AE13: C | AF13: C | AG13: C | AH13: C | AI13: F | AJ13: C | AK13: F | AL13: EP | AW13: =IFERROR(COUNTIF(V13:AV13,"C")/COUNTA(V13:AV13),0) -> 0.82352941
A14: MANTENIMIENTO | U14: P | V14: C | W14: C | X14: C | Y14: C | Z14: C | AA14: C | AB14: C | AC14: C | AD14: C | AE14: C | AF14: C | AG14: C | AH14: C | AI14: F | AJ14: C | AK14: F | AL14: EP | AW14: =IFERROR(COUNTIF(V14:AV14,"C")/COUNTA(V14:AV14),0) -> 0.82352941
A15: DESARROLLOS MINEROS | U15: P | V15: C | W15: C | X15: C | Y15: C | Z15: C | AA15: C | AB15: C | AC15: C | AD15: C | AE15: C | AF15: C | AG15: C | AH15: C | AI15: F | AJ15: C | AK15: F | AL15: EP | AW15: =IFERROR(COUNTIF(V15:AV15,"C")/COUNTA(V15:AV15),0) -> 0.82352941
A16: CAMPAMENTO | V16: C | W16: C | X16: C | Y16: C | Z16: C | AA16: C | AB16: C | AC16: C | AD16: C | AE16: C | AF16: C | AG16: C | AH16: C | AI16: F | AJ16: C | AK16: F | AL16: EP | AW16: =IFERROR(COUNTIF(V16:AV16,"C")/COUNTA(V16:AV16),0) -> 0.82352941
A17: COMEDOR | V17: C | W17: C | X17: C | Y17: C | Z17: C | AA17: C | AB17: C | AC17: C | AD17: C | AE17: C | AF17: C | AG17: C | AH17: C | AI17: F | AJ17: C | AK17: F | AL17: EP | AW17: =IFERROR(COUNTIF(V17:AV17,"C")/COUNTA(V17:AV17),0) -> 0.82352941
A18: MEDIO AMBIENTE | U18: P | V18: C | W18: C | X18: C | Y18: C | Z18: C | AA18: C | AB18: C | AC18: C | AD18: C | AE18: C | AF18: C | AG18: C | AH18: C | AI18: F | AJ18: C | AK18: F | AL18: EP | AW18: =IFERROR(COUNTIF(V18:AV18,"C")/COUNTA(V18:AV18),0) -> 0.82352941
A19: GEOLOGÍA | U19: P | V19: C | W19: C | X19: C | Y19: C | Z19: C | AA19: C | AB19: C | AC19: C | AD19: C | AE19: C | AF19: C | AG19: C | AH19: C | AI19: F | AJ19: C | AK19: F | AL19: EP | AW19: =IFERROR(COUNTIF(V19:AV19,"C")/COUNTA(V19:AV19),0) -> 0.82352941
A20: LOGÍSTICA | U20: P | V20: C | W20: C | X20: C | Y20: C | Z20: C | AA20: C | AB20: C | AC20: C | AD20: C | AE20: C | AF20: C | AG20: C | AH20: C | AI20: F | AJ20: C | AK20: F | AL20: EP | AW20: =IFERROR(COUNTIF(V20:AV20,"C")/COUNTA(V20:AV20),0) -> 0.82352941
A21: RENTACAR | U21: P | V21: C | W21: C | X21: C | Y21: C | Z21: C | AA21: C | AB21: C | AC21: C | AD21: C | AE21: C | AF21: C | AG21: C | AH21: C | AI21: F | AJ21: C | AK21: F | AL21: EP | AW21: =IFERROR(COUNTIF(V21:AV21,"C")/COUNTA(V21:AV21),0) -> 0.82352941
A22: IRENE | U22: P | V22: C | W22: C | X22: C | Y22: C | Z22: C | AA22: C | AB22: C | AC22: C | AD22: C | AE22: C | AF22: C | AG22: C | AH22: C | AI22: F | AJ22: C | AK22: F | AL22: EP | AW22: =IFERROR(COUNTIF(V22:AV22,"C")/COUNTA(V22:AV22),0) -> 0.82352941
A23: OBRAS CIVILES | U23: P | V23: C | W23: C | X23: C | Y23: C | Z23: C | AA23: C | AB23: C | AC23: C | AD23: C | AE23: C | AF23: C | AG23: C | AH23: C | AI23: F | AJ23: C | AK23: F | AL23: EP | AW23: =IFERROR(COUNTIF(V23:AV23,"C")/COUNTA(V23:AV23),0) -> 0.82352941
A24: DIAMANTINA | U24: P | V24: C | W24: C | X24: C | Y24: C | Z24: C | AA24: C | AB24: C | AC24: C | AD24: C | AE24: C | AF24: C | AG24: C | AH24: C | AI24: F | AJ24: C | AK24: F | AL24: EP | AW24: =IFERROR(COUNTIF(V24:AV24,"C")/COUNTA(V24:AV24),0) -> 0.82352941
A25: CONGEMIN | U25: P | V25: C | W25: C | X25: C | Y25: C | Z25: C | AA25: C | AB25: C | AC25: C | AD25: C | AE25: C | AF25: C | AG25: C | AH25: C | AI25: F | AJ25: C | AK25: F | AL25: EP | AW25: =IFERROR(COUNTIF(V25:AV25,"C")/COUNTA(V25:AV25),0) -> 0.82352941
A26: % | V26: =COUNTIF(V11:V25,"C")/15 -> 1 | W26: =COUNTIF(W11:W25,"C")/15 -> 1 | X26: =COUNTIF(X11:X25,"C")/15 -> 1 | Y26: =COUNTIF(Y11:Y25,"C")/15 -> 1 | Z26: =COUNTIF(Z11:Z25,"C")/15 -> 1 | AA26: =COUNTIF(AA11:AA25,"C")/15 -> 1 | AB26: =COUNTIF(AB11:AB25,"C")/15 -> 1 | AC26: =COUNTIF(AC11:AC25,"C")/15 -> 1 | ... AV26: =COUNTIF(AV11:AV25,"C")/15 -> 0

Sheet CUMPLIMIENTO GUARDIAS
A1: Área Responsable | B1: Mes | C1: N° Mes | D1: Tema | E1: Guardia A | F1: Guardia B | G1: Guardia C | H1: Total cumplidas | I1: % Cumplimiento Tema | J1: Estado Programa
A2: MINA CANDELARIA | B2: ENERO | C2: 1 | D2: Respuesta a Emergencias por Áreas específicas. | E2: C | F2: C | G2: C | H2: =COUNTIF(E2:G2,"C") -> 3 | I2: =H2/3 -> 1 | J2: ='PROGRAMA LECTURA'!V11 -> C
A3: MINA CANDELARIA | B3: ENERO | C3: 1 | D3: Primeros Auxilios | E3: C | F3: C | G3: C | H3: =COUNTIF(E3:G3,"C") -> 3 | I3: =H3/3 -> 1 | J3: ='PROGRAMA LECTURA'!W11 -> C
A4: MINA CANDELARIA | B4: FEBRERO | C4: 2 | D4: Notificación, investigación y reporte de incidentes , incidentes peligrosos y accidentes de trabajo. | E4: C | F4: C | G4: C | H4: =COUNTIF(E4:G4,"C") -> 3 | I4: =H4/3 -> 1 | J4: ='PROGRAMA LECTURA'!X11 -> C
A5: MINA CANDELARIA | B5: FEBRERO | C5: 2 | D5: IPERC | E5: C | F5: C | G5: C | H5: =COUNTIF(E5:G5,"C") -> 3 | I5: =H5/3 -> 1 | J5: ='PROGRAMA LECTURA'!Y11 -> C
A6: MINA CANDELARIA | B6: MARZO | C6: 3 | D6: Trabajos en Altura | E6: C | F6: C | G6: C | H6: =COUNTIF(E6:G6,"C") -> 3 | I6: =H6/3 -> 1 | J6: ='PROGRAMA LECTURA'!Z11 -> C
A7: MINA CANDELARIA | B7: MARZO | C7: 3 | D7: Prevención y Protección Contra Incendio | E7: C | F7: C | G7: C | H7: =COUNTIF(E7:G7,"C") -> 3 | I7: =H7/3 -> 1 | J7: ='PROGRAMA LECTURA'!AA11 -> C
A8: MINA CANDELARIA | B8: ABRIL | C8: 4 | D8: Gestión de la Seguridad y Salud Ocupacional basado en el Reglamento de Seguridad y Salud Ocupacional, Política de Seguridad, Salud Ocupacional y Medio Ambiente. | E8: C | F8: C | G8: C | H8: =COUNTIF(E8:G8,"C") -> 3 | I8: =H8/3 -> 1 | J8: ='PROGRAMA LECTURA'!AB11 -> C
A9: MINA CANDELARIA | B9: ABRIL | C9: 4 | D9: Mapa de riesgos | E9: C | F9: C | G9: C | H9: =COUNTIF(E9:G9,"C") -> 3 | I9: =H9/3 -> 1 | J9: ='PROGRAMA LECTURA'!AC11 -> C
A10: MINA CANDELARIA | B10: ABRIL | C10: 4 | D10: Estándares y procedimiento escrito de trabajo seguro por actividades | E10: C | F10: C | G10: C | H10: =COUNTIF(E10:G10,"C") -> 3 | I10: =H10/3 -> 1 | J10: ='PROGRAMA LECTURA'!AD11 -> C
A11: MINA CANDELARIA | B11: MAYO | C11: 5 | D11: Significado y uso de código de señales y colores. | E11: C | F11: C | G11: C | H11: =COUNTIF(E11:G11,"C") -> 3 | I11: =H11/3 -> 1 | J11: ='PROGRAMA LECTURA'!AE11 -> C
A12: MINA CANDELARIA | B12: MAYO | C12: 5 | D12: Auditoría, fiscalización e Inspecciones de Seguridad | E12: C | F12: C | G12: C | H12: =COUNTIF(E12:G12,"C") -> 3 | I12: =H12/3 -> 1 | J12: ='PROGRAMA LECTURA'!AF11 -> C
A13: MINA CANDELARIA | B13: JUNIO | C13: 6 | D13: IPERC | E13: C | F13: C | G13: C | H13: =COUNTIF(E13:G13,"C") -> 3 | I13: =H13/3 -> 1 | J13: ='PROGRAMA LECTURA'!AG11 -> C
A14: MINA CANDELARIA | B14: JUNIO | C14: 6 | D14: Higiene Ocupacional (Agentes Físicos, Químicos y Biológicos) Disposición de residuos sólidos. Control de Sustancias peligrosas. | E14: C | F14: C | G14: C | H14: =COUNTIF(E14:G14,"C") -> 3 | I14: =H14/3 -> 1 | J14: ='PROGRAMA LECTURA'!AH11 -> C
A15: MINA CANDELARIA | B15: JUNIO | C15: 6 | D15: Manejo defensivo y/o transporte de personal | E15: F | F15: F | G15: F | H15: =COUNTIF(E15:G15,"C") -> 0 | I15: =H15/3 -> 0 | J15: ='PROGRAMA LECTURA'!AI11 -> F
A16: MINA CANDELARIA | B16: JULIO | C16: 7 | D16: Respuesta a Emergencias por Áreas específicas. | E16: C | F16: C | G16: C | H16: =COUNTIF(E16:G16,"C") -> 3 | I16: =H16/3 -> 1 | J16: ='PROGRAMA LECTURA'!AJ11 -> C
A17: MINA CANDELARIA | B17: JULIO | C17: 7 | D17: Comité de Seguridad y Salud Ocupacional. Reglamento Interno de Seguridad y Salud Ocupaciona. Programa Anual de Seguridad y Salud Ocupacional. | H17: =COUNTIF(E17:G17,"C") -> 0 | I17: =H17/3 -> 0 | J17: ='PROGRAMA LECTURA'!AK11 -> F
A18: MINA CANDELARIA | B18: JULIO | C18: 7 | D18: Seguridad en la Oficina y Ergonomía. | E18: EP | F18: EP | G18: EP | H18: =COUNTIF(E18:G18,"C") -> 0 | I18: =H18/3 -> 0 | J18: ='PROGRAMA LECTURA'!AL11 -> EP
A19: MINA CANDELARIA | B19: AGOSTO | C19: 8 | D19: Riesgos Psicosociales | H19: =COUNTIF(E19:G19,"C") -> 0 | I19: =H19/3 -> 0 | J19: ='PROGRAMA LECTURA'!AM11 -> 0
A20: MINA CANDELARIA | B20: AGOSTO | C20: 8 | D20: Riesgos Eléctricos | H20: =COUNTIF(E20:G20,"C") -> 0 | I20: =H20/3 -> 0 | J20: ='PROGRAMA LECTURA'!AN11 -> 0
A21: MINA CANDELARIA | B21: AGOSTO | C21: 8 | D21: Prevención de accidente por desprendimiento de rocas | H21: =COUNTIF(E21:G21,"C") -> 0 | I21: =H21/3 -> 0 | J21: ='PROGRAMA LECTURA'!AO11 -> 0
A22: MINA CANDELARIA | B22: SETIEMBRE | C22: 9 | D22: Prevención de accidente por gaseamiento | H22: =COUNTIF(E22:G22,"C") -> 0 | I22: =H22/3 -> 0 | J22: ='PROGRAMA LECTURA'!AP11 -> 0
A23: MINA CANDELARIA | B23: SETIEMBRE | C23: 9 | D23: Uso de Equipo de Protección Personal (EPP) | H23: =COUNTIF(E23:G23,"C") -> 0 | I23: =H23/3 -> 0 | J23: ='PROGRAMA LECTURA'!AQ11 -> 0
A24: MINA CANDELARIA | B24: OCTUBRE | C24: 10 | D24: IPERC | H24: =COUNTIF(E24:G24,"C") -> 0 | I24: =H24/3 -> 0 | J24: ='PROGRAMA LECTURA'!AR11 -> 0
A25: MINA CANDELARIA | B25: OCTUBRE | C25: 10 | D25: Prevención y Protección Contra Incendio | H25: =COUNTIF(E25:G25,"C") -> 0 | I25: =H25/3 -> 0 | J25: ='PROGRAMA LECTURA'!AS11 -> 0
A26: MINA CANDELARIA | B26: NOVIEMBRE | C26: 11 | D26: Liderazgo y motivación: Seguridad basada en el Comportamiento. | H26: =COUNTIF(E26:G26,"C") -> 0 | I26: =H26/3 -> 0 | J26: ='PROGRAMA LECTURA'!AT11 -> 0
A27: MINA CANDELARIA | B27: NOVIEMBRE | C27: 11 | D27: Primeros Auxilios | H27: =COUNTIF(E27:G27,"C") -> 0 | I27: =H27/3 -> 0 | J27: ='PROGRAMA LECTURA'!AU11 -> 0
A28: MINA CANDELARIA | B28: DICIEMBRE | C28: 12 | D28: Respuesta a Emergencias por Áreas específicas. | H28: =COUNTIF(E28:G28,"C") -> 0 | I28: =H28/3 -> 0 | J28: ='PROGRAMA LECTURA'!AV11 -> 0
A29: PLANTA MAHUARA | B29: ENERO | C29: 1 | D29: Respuesta a Emergencias por Áreas específicas. | E29: C | F29: C | G29: C | H29: =COUNTIF(E29:G29,"C") -> 3 | I29: =H29/3 -> 1 | J29: ='PROGRAMA LECTURA'!V12 -> C
A30: PLANTA MAHUARA | B30: ENERO | C30: 1 | D30: Primeros Auxilios | E30: C | F30: C | G30: C | H30: =COUNTIF(E30:G30,"C") -> 3 | I30: =H30/3 -> 1 | J30: ='PROGRAMA LECTURA'!W12 -> C
A31: PLANTA MAHUARA | B31: FEBRERO | C31: 2 | D31: Notificación, investigación y reporte de incidentes , incidentes peligrosos y accidentes de trabajo. | E31: C | F31: C | G31: C | H31: =COUNTIF(E31:G31,"C") -> 3 | I31: =H31/3 -> 1 | J31: ='PROGRAMA LECTURA'!X12 -> C
A32: PLANTA MAHUARA | B32: FEBRERO | C32: 2 | D32: IPERC | E32: C | F32: C | G32: C | H32: =COUNTIF(E32:G32,"C") -> 3 | I32: =H32/3 -> 1 | J32: ='PROGRAMA LECTURA'!Y12 -> C
A33: PLANTA MAHUARA | B33: MARZO | C33: 3 | D33: Trabajos en Altura | E33: C | F33: C | G33: C | H33: =COUNTIF(E33:G33,"C") -> 3 | I33: =H33/3 -> 1 | J33: ='PROGRAMA LECTURA'!Z12 -> C
A34: PLANTA MAHUARA | B34: MARZO | C34: 3 | D34: Prevención y Protección Contra Incendio | E34: C | F34: C | G34: C | H34: =COUNTIF(E34:G34,"C") -> 3 | I34: =H34/3 -> 1 | J34: ='PROGRAMA LECTURA'!AA12 -> C
A35: PLANTA MAHUARA | B35: ABRIL | C35: 4 | D35: Gestión de la Seguridad y Salud Ocupacional basado en el Reglamento de Seguridad y Salud Ocupacional, Política de Seguridad, Salud Ocupacional y Medio Ambiente. | E35: C | F35: C | G35: C | H35: =COUNTIF(E35:G35,"C") -> 3 | I35: =H35/3 -> 1 | J35: ='PROGRAMA LECTURA'!AB12 -> C
A36: PLANTA MAHUARA | B36: ABRIL | C36: 4 | D36: Mapa de riesgos | E36: C | F36: C | G36: C | H36: =COUNTIF(E36:G36,"C") -> 3 | I36: =H36/3 -> 1 | J36: ='PROGRAMA LECTURA'!AC12 -> C
A37: PLANTA MAHUARA | B37: ABRIL | C37: 4 | D37: Estándares y procedimiento escrito de trabajo seguro por actividades | E37: C | F37: C | G37: C | H37: =COUNTIF(E37:G37,"C") -> 3 | I37: =H37/3 -> 1 | J37: ='PROGRAMA LECTURA'!AD12 -> C
A38: PLANTA MAHUARA | B38: MAYO | C38: 5 | D38: Significado y uso de código de señales y colores. | E38: C | F38: C | G38: C | H38: =COUNTIF(E38:G38,"C") -> 3 | I38: =H38/3 -> 1 | J38: ='PROGRAMA LECTURA'!AE12 -> C
A39: PLANTA MAHUARA | B39: MAYO | C39: 5 | D39: Auditoría, fiscalización e Inspecciones de Seguridad | E39: C | F39: C | G39: C | H39: =COUNTIF(E39:G39,"C") -> 3 | I39: =H39/3 -> 1 | J39: ='PROGRAMA LECTURA'!AF12 -> C
A40: PLANTA MAHUARA | B40: JUNIO | C40: 6 | D40: IPERC | E40: C | F40: C | G40: C | H40: =COUNTIF(E40:G40,"C") -> 3 | I40: =H40/3 -> 1 | J40: ='PROGRAMA LECTURA'!AG12 -> C
...

Sheet DASHBOARD
A1: DASHBOARD DE CUMPLIMIENTO – CAPACITACIONES ANEXO 6
G2: =IF(F2="Cumplido",1,0) -> 0
A3: Área seleccionada | B3: MINA CANDELARIA | G3: =IF(F3="Cumplido",1,0) -> 0
G4: =IF(F4="Cumplido",1,0) -> 0
A5: Cumplimiento del área | D5: Cumplidas | G5: =IF(F5="Cumplido",1,0) -> 0 | J5: En proceso
A6: =IFERROR(D6/(COUNTIFS('PROGRAMA LECTURA'!$A$11:$A$25,$B$3,'PROGRAMA LECTURA'!$V$11:$V$25,"<>")+COUNTIFS('PROGRAMA LECTURA'!$A$11:$A$25,$B$3,'PROGRAMA LECTURA'!$W$11:$W$25,"<>")+COUNTIFS('PROGRAMA LECTURA'!$A$11:$A$25,$B$3,'PROGRAMA LECTURA'!$X$11:$X$25,"<>")+COUNTIFS('PROGRAMA LECTURA'!$A$11:$A$25,$B$3,'PROGRAMA LECTURA'!$Y$11:$Y$25,"<>")+COUNTIFS('PROGRAMA LECTURA'!$A$11:$A$25,$B$3,'PROGRAMA LECTURA'!$Z$11:$Z$25,"<>")+COUNTIFS('PROGRAMA LECTURA'!$A$11:$A$25,$B$3,'PROGRAMA LECTURA'!$AA$11:$AA$25,"<>")+COUNTIFS('PROGRAMA LECTURA'!$A$11:$A$25,$B$3,'PROGRAMA LECTURA'!$AB$11:$AB$25,"<>")+COUNTIFS('PROGRAMA LECTURA'!$A$11:$A$25,$B$3,'PROGRAMA LECTURA'!$AC$11:$AC$25,"<>")+COUNTIFS('PROGRAMA LECTURA'!$A$11:$A$25,$B$3,'PROGRAMA LECTURA'!$AD$11:$AD$25,"<>")+COUNTIFS('PROGRAMA LECTURA'!$A$11:$A$25,$B$3,'PROGRAMA LECTURA'!$AE$11:$AE$25,"<>")+COUNTIFS('PROGRAMA LECTURA'!$A$11:$A$25,$B$3,'PROGRAMA LECTURA'!$AF$11:$AF$25,"<>")+COUNTIFS('PROGRAMA LECTURA'!$A$11:$A$25,$B$3,'PROGRAMA LECTURA'!$AG$11:$AG$25,"<>")+COUNTIFS('PROGRAMA LECTURA'!$A$11:$A$25,$B$3,'PROGRAMA LECTURA'!$AH$11:$AH$25,"<>")+COUNTIFS('PROGRAMA LECTURA'!$A$11:$A$25,$B$3,'PROGRAMA LECTURA'!$AI$11:$AI$25,"<>")+COUNTIFS('PROGRAMA LECTURA'!$A$11:$A$25,$B$3,'PROGRAMA LECTURA'!$AJ$11:$AJ$25,"<>")+COUNTIFS('PROGRAMA LECTURA'!$A$11:$A$25,$B$3,'PROGRAMA LECTURA'!$AK$11:$AK$25,"<>")+COUNTIFS('PROGRAMA LECTURA'!$A$11:$A$25,$B$3,'PROGRAMA LECTURA'!$AL$11:$AL$25,"<>")+COUNTIFS('PROGRAMA LECTURA'!$A$11:$A$25,$B$3,'PROGRAMA LECTURA'!$AM$11:$AM$25,"<>")+COUNTIFS('PROGRAMA LECTURA'!$A$11:$A$25,$B$3,'PROGRAMA LECTURA'!$AN$11:$AN$25,"<>")+COUNTIFS('PROGRAMA LECTURA'!$A$11:$A$25,$B$3,'PROGRAMA LECTURA'!$AO$11:$AO$25,"<>")+COUNTIFS('PROGRAMA LECTURA'!$A$11:$A$25,$B$3,'PROGRAMA LECTURA'!$AP$11:$AP$25,"<>")+COUNTIFS('PROGRAMA LECTURA'!$A$11:$A$25,$B$3,'PROGRAMA LECTURA'!$AQ$11:$AQ$25,"<>")+COUNTIFS('PROGRAMA LECTURA'!$A$11:$A$25,$B$3,'PROGRAMA LECTURA'!$AR$11:$AR$25,"<>")+COUNTIFS('PROGRAMA LECTURA'!$A$11:$A$25,$B$3,'PROGRAMA LECTURA'!$AS$11:$AS$25,"<>")+COUNTIFS('PROGRAMA LECTURA'!$A$11:$A$25,$B$3,'PROGRAMA LECTURA'!$AT$11:$AT$25,"<>")+COUNTIFS('PROGRAMA LECTURA'!$A$11:$A$25,$B$3,'PROGRAMA LECTURA'!$AU$11:$AU$25,"<>")+COUNTIFS('PROGRAMA LECTURA'!$A$11:$A$25,$B$3,'PROGRAMA LECTURA'!$AV$11:$AV$25,"<>")),0) -> 0.82352941 | D6: =COUNTIFS('PROGRAMA LECTURA'!$A$11:$A$25,$B$3,'PROGRAMA LECTURA'!$V$11:$V$25,"C")+COUNTIFS('PROGRAMA LECTURA'!$A$11:$A$25,$B$3,'PROGRAMA LECTURA'!$W$11:$W$25,"C")+COUNTIFS('PROGRAMA LECTURA'!$A$11:$A$25,$B$3,'PROGRAMA LECTURA'!$X$11:$X$25,"C")+COUNTIFS('PROGRAMA LECTURA'!$A$11:$A$25,$B$3,'PROGRAMA LECTURA'!$Y$11:$Y$25,"C")+COUNTIFS('PROGRAMA LECTURA'!$A$11:$A$25,$B$3,'PROGRAMA LECTURA'!$Z$11:$Z$25,"C")+COUNTIFS('PROGRAMA LECTURA'!$A$11:$A$25,$B$3,'PROGRAMA LECTURA'!$AA$11:$AA$25,"C")+COUNTIFS('PROGRAMA LECTURA'!$A$11:$A$25,$B$3,'PROGRAMA LECTURA'!$AB$11:$AB$25,"C")+COUNTIFS('PROGRAMA LECTURA'!$A$11:$A$25,$B$3,'PROGRAMA LECTURA'!$AC$11:$AC$25,"C")+COUNTIFS('PROGRAMA LECTURA'!$A$11:$A$25,$B$3,'PROGRAMA LECTURA'!$AD$11:$AD$25,"C")+COUNTIFS('PROGRAMA LECTURA'!$A$11:$A$25,$B$3,'PROGRAMA LECTURA'!$AE$11:$AE$25,"C")+COUNTIFS('PROGRAMA LECTURA'!$A$11:$A$25,$B$3,'PROGRAMA LECTURA'!$AF$11:$AF$25,"C")+COUNTIFS('PROGRAMA LECTURA'!$A$11:$A$25,$B$3,'PROGRAMA LECTURA'!$AG$11:$AG$25,"C")+COUNTIFS('PROGRAMA LECTURA'!$A$11:$A$25,$B$3,'PROGRAMA LECTURA'!$AH$11:$AH$25,"C")+COUNTIFS('PROGRAMA LECTURA'!$A$11:$A$25,$B$3,'PROGRAMA LECTURA'!$AI$11:$AI$25,"C")+COUNTIFS('PROGRAMA LECTURA'!$A$11:$A$25,$B$3,'PROGRAMA LECTURA'!$AJ$11:$AJ$25,"C")+COUNTIFS('PROGRAMA LECTURA'!$A$11:$A$25,$B$3,'PROGRAMA LECTURA'!$AK$11:$AK$25,"C")+COUNTIFS('PROGRAMA LECTURA'!$A$11:$A$25,$B$3,'PROGRAMA LECTURA'!$AL$11:$AL$25,"C")+COUNTIFS('PROGRAMA LECTURA'!$A$11:$A$25,$B$3,'PROGRAMA LECTURA'!$AM$11:$AM$25,"C")+COUNTIFS('PROGRAMA LECTURA'!$A$11:$A$25,$B$3,'PROGRAMA LECTURA'!$AN$11:$AN$25,"C")+COUNTIFS('PROGRAMA LECTURA'!$A$11:$A$25,$B$3,'PROGRAMA LECTURA'!$AO$11:$AO$25,"C")+COUNTIFS('PROGRAMA LECTURA'!$A$11:$A$25,$B$3,'PROGRAMA LECTURA'!$AP$11:$AP$25,"C")+COUNTIFS('PROGRAMA LECTURA'!$A$11:$A$25,$B$3,'PROGRAMA LECTURA'!$AQ$11:$AQ$25,"C")+COUNTIFS('PROGRAMA LECTURA'!$A$11:$A$25,$B$3,'PROGRAMA LECTURA'!$AR$11:$AR$25,"C")+COUNTIFS('PROGRAMA LECTURA'!$A$11:$A$25,$B$3,'PROGRAMA LECTURA'!$AS$11:$AS$25,"C")+COUNTIFS('PROGRAMA LECTURA'!$A$11:$A$25,$B$3,'PROGRAMA LECTURA'!$AT$11:$AT$25,"C")+COUNTIFS('PROGRAMA LECTURA'!$A$11:$A$25,$B$3,'PROGRAMA LECTURA'!$AU$11:$AU$25,"C")+COUNTIFS('PROGRAMA LECTURA'!$A$11:$A$25,$B$3,'PROGRAMA LECTURA'!$AV$11:$AV$25,"C") -> 14 | G6: =IF(F6="Cumplido",1,0) -> 0 | J6: =COUNTIFS('PROGRAMA LECTURA'!$A$11:$A$25,$B$3,'PROGRAMA LECTURA'!$V$11:$V$25,"EP")+COUNTIFS('PROGRAMA LECTURA'!$A$11:$A$25,$B$3,'PROGRAMA LECTURA'!$W$11:$W$25,"EP")+COUNTIFS('PROGRAMA LECTURA'!$A$11:$A$25,$B$3,'PROGRAMA LECTURA'!$X$11:$X$25,"EP")+COUNTIFS('PROGRAMA LECTURA'!$A$11:$A$25,$B$3,'PROGRAMA LECTURA'!$Y$11:$Y$25,"EP")+COUNTIFS('PROGRAMA LECTURA'!$A$11:$A$25,$B$3,'PROGRAMA LECTURA'!$Z$11:$Z$25,"EP")+COUNTIFS('PROGRAMA LECTURA'!$A$11:$A$25,$B$3,'PROGRAMA LECTURA'!$AA$11:$AA$25,"EP")+COUNTIFS('PROGRAMA LECTURA'!$A$11:$A$25,$B$3,'PROGRAMA LECTURA'!$AB$11:$AB$25,"EP")+COUNTIFS('PROGRAMA LECTURA'!$A$11:$A$25,$B$3,'PROGRAMA LECTURA'!$AC$11:$AC$25,"EP")+COUNTIFS('PROGRAMA LECTURA'!$A$11:$A$25,$B$3,'PROGRAMA LECTURA'!$AD$11:$AD$25,"EP")+COUNTIFS('PROGRAMA LECTURA'!$A$11:$A$25,$B$3,'PROGRAMA LECTURA'!$AE$11:$AE$25,"EP")+COUNTIFS('PROGRAMA LECTURA'!$A$11:$A$25,$B$3,'PROGRAMA LECTURA'!$AF$11:$AF$25,"EP")+COUNTIFS('PROGRAMA LECTURA'!$A$11:$A$25,$B$3,'PROGRAMA LECTURA'!$AG$11:$AG$25,"EP")+COUNTIFS('PROGRAMA LECTURA'!$A$11:$A$25,$B$3,'PROGRAMA LECTURA'!$AH$11:$AH$25,"EP")+COUNTIFS('PROGRAMA LECTURA'!$A$11:$A$25,$B$3,'PROGRAMA LECTURA'!$AI$11:$AI$25,"EP")+COUNTIFS('PROGRAMA LECTURA'!$A$11:$A$25,$B$3,'PROGRAMA LECTURA'!$AJ$11:$AJ$25,"EP")+COUNTIFS('PROGRAMA LECTURA'!$A$11:$A$25,$B$3,'PROGRAMA LECTURA'!$AK$11:$AK$25,"EP")+COUNTIFS('PROGRAMA LECTURA'!$A$11:$A$25,$B$3,'PROGRAMA LECTURA'!$AL$11:$AL$25,"EP")+COUNTIFS('PROGRAMA LECTURA'!$A$11:$A$25,$B$3,'PROGRAMA LECTURA'!$AM$11:$AM$25,"EP")+COUNTIFS('PROGRAMA LECTURA'!$A$11:$A$25,$B$3,'PROGRAMA LECTURA'!$AN$11:$AN$25,"EP")+COUNTIFS('PROGRAMA LECTURA'!$A$11:$A$25,$B$3,'PROGRAMA LECTURA'!$AO$11:$AO$25,"EP")+COUNTIFS('PROGRAMA LECTURA'!$A$11:$A$25,$B$3,'PROGRAMA LECTURA'!$AP$11:$AP$25,"EP")+COUNTIFS('PROGRAMA LECTURA'!$A$11:$A$25,$B$3,'PROGRAMA LECTURA'!$AQ$11:$AQ$25,"EP")+COUNTIFS('PROGRAMA LECTURA'!$A$11:$A$25,$B$3,'PROGRAMA LECTURA'!$AR$11:$AR$25,"EP")+COUNTIFS('PROGRAMA LECTURA'!$A$11:$A$25,$B$3,'PROGRAMA LECTURA'!$AS$11:$AS$25,"EP")+COUNTIFS('PROGRAMA LECTURA'!$A$11:$A$25,$B$3,'PROGRAMA LECTURA'!$AT$11:$AT$25,"EP")+COUNTIFS('PROGRAMA LECTURA'!$A$11:$A$25,$B$3,'PROGRAMA LECTURA'!$AU$11:$AU$25,"EP")+COUNTIFS('PROGRAMA LECTURA'!$A$11:$A$25,$B$3,'PROGRAMA LECTURA'!$AV$11:$AV$25,"EP") -> 1
G7: =IF(F7="Cumplido",1,0) -> 0
G8: =IF(F8="Cumplido",1,0) -> 0
G9: =IF(F9="Cumplido",1,0) -> 0
G10: =IF(F10="Cumplido",1,0) -> 0
A11: Estado | B11: Cantidad | D11: Cumplimiento general | G11: =IF(F11="Cumplido",1,0) -> 0
A12: Cumplidas | B12: =D6 -> 14 | D12: =IFERROR(COUNTIF('PROGRAMA LECTURA'!$V$11:$AV$25,"C")/COUNTA('PROGRAMA LECTURA'!$V$11:$AV$25),0) -> 0.82352941 | G12: =IF(F12="Cumplido",1,0) -> 0
A13: Faltantes | B13: =G6 -> 0 | G13: =IF(F13="Cumplido",1,0) -> 0
A14: En proceso | B14: =J6 -> 1 | G14: =IF(F14="Cumplido",1,0) -> 0
G15: =IF(F15="Cumplido",1,0) -> 0
D16: Leyenda: C = Cumplida | F = Falta | EP = En Proceso | G16: =IF(F16="Cumplido",1,0) -> 0
G17: =IF(F17="Cumplido",1,0) -> 0
A18: Área | B18: % Cumplimiento | G18: =IF(F18="Cumplido",1,0) -> 0
A19: ='PROGRAMA LECTURA'!A11 -> MINA CANDELARIA | B19: ='PROGRAMA LECTURA'!AW11 -> 0.82352941 | G19: =IF(F19="Cumplido",1,0) -> 0
A20: ='PROGRAMA LECTURA'!A12 -> PLANTA MAHUARA | B20: ='PROGRAMA LECTURA'!AW12 -> 0.82352941 | G20: =IF(F20="Cumplido",1,0) -> 0
A21: ='PROGRAMA LECTURA'!A13 -> ADMINISTRACIÓN | B21: ='PROGRAMA LECTURA'!AW13 -> 0.82352941 | G21: =IF(F21="Cumplido",1,0) -> 0
A22: ='PROGRAMA LECTURA'!A14 -> MANTENIMIENTO | B22: ='PROGRAMA LECTURA'!AW14 -> 0.82352941 | G22: =IF(F22="Cumplido",1,0) -> 0
A23: ='PROGRAMA LECTURA'!A15 -> DESARROLLOS MINEROS | B23: ='PROGRAMA LECTURA'!AW15 -> 0.82352941 | G23: =IF(F23="Cumplido",1,0) -> 0
A24: ='PROGRAMA LECTURA'!A16 -> CAMPAMENTO | B24: ='PROGRAMA LECTURA'!AW16 -> 0.82352941 | G24: =IF(F24="Cumplido",1,0) -> 0
A25: ='PROGRAMA LECTURA'!A17 -> COMEDOR | B25: ='PROGRAMA LECTURA'!AW17 -> 0.82352941
A26: ='PROGRAMA LECTURA'!A18 -> MEDIO AMBIENTE | B26: ='PROGRAMA LECTURA'!AW18 -> 0.82352941
A27: ='PROGRAMA LECTURA'!A19 -> GEOLOGÍA | B27: ='PROGRAMA LECTURA'!AW19 -> 0.82352941
A28: ='PROGRAMA LECTURA'!A20 -> LOGÍSTICA | B28: ='PROGRAMA LECTURA'!AW20 -> 0.82352941
A29: ='PROGRAMA LECTURA'!A21 -> RENTACAR | B29: ='PROGRAMA LECTURA'!AW21 -> 0.82352941
A30: ='PROGRAMA LECTURA'!A22 -> IRENE | B30: ='PROGRAMA LECTURA'!AW22 -> 0.82352941
A31: ='PROGRAMA LECTURA'!A23 -> OBRAS CIVILES | B31: ='PROGRAMA LECTURA'!AW23 -> 0.82352941
A32: ='PROGRAMA LECTURA'!A24 -> DIAMANTINA | B32: ='PROGRAMA LECTURA'!AW24 -> 0.82352941
A33: ='PROGRAMA LECTURA'!A25 -> CONGEMIN | B33: ='PROGRAMA LECTURA'!AW25 -> 0.82352941

Sheet MAPEO TEMAS
A1: Área | B1: Mes | C1: N° Mes | D1: Tema | E1: Estado | F1: % Guardias | G1: Guardia A | H1: Guardia B | I1: Guardia C | J1: Programado al corte | K1: Cumplimiento programa | L1: Fila Guardia
A2: MINA CANDELARIA | B2: ENERO | C2: 1 | D2: Respuesta a Emergencias por Áreas específicas. | E2: ='CUMPLIMIENTO GUARDIAS'!J2 -> C | F2: ='CUMPLIMIENTO GUARDIAS'!I2 -> 1 | G2: ='CUMPLIMIENTO GUARDIAS'!E2 -> C | H2: ='CUMPLIMIENTO GUARDIAS'!F2 -> C | I2: ='CUMPLIMIENTO GUARDIAS'!G2 -> C | J2: =--(C2<=MATCH('DASHBOARD AVANZADO'!$G$3,'DASHBOARD AVANZADO'!$Q$1:$Q$12,0)) -> 1 | K2: =IF(E2="C",1,0) -> 1 | L2: 2
A3: MINA CANDELARIA | B3: ENERO | C3: 1 | D3: Primeros Auxilios | E3: ='CUMPLIMIENTO GUARDIAS'!J3 -> C | F3: ='CUMPLIMIENTO GUARDIAS'!I3 -> 1 | G3: ='CUMPLIMIENTO GUARDIAS'!E3 -> C | H3: ='CUMPLIMIENTO GUARDIAS'!F3 -> C | I3: ='CUMPLIMIENTO GUARDIAS'!G3 -> C | J3: =--(C3<=MATCH('DASHBOARD AVANZADO'!$G$3,'DASHBOARD AVANZADO'!$Q$1:$Q$12,0)) -> 1 | K3: =IF(E3="C",1,0) -> 1 | L3: 3
A4: MINA CANDELARIA | B4: FEBRERO | C4: 2 | D4: Notificación, investigación y reporte de incidentes , incidentes peligrosos y accidentes de trabajo. | E4: ='CUMPLIMIENTO GUARDIAS'!J4 -> C | F4: ='CUMPLIMIENTO GUARDIAS'!I4 -> 1 | G4: ='CUMPLIMIENTO GUARDIAS'!E4 -> C | H4: ='CUMPLIMIENTO GUARDIAS'!F4 -> C | I4: ='CUMPLIMIENTO GUARDIAS'!G4 -> C | J4: =--(C4<=MATCH('DASHBOARD AVANZADO'!$G$3,'DASHBOARD AVANZADO'!$Q$1:$Q$12,0)) -> 1 | K4: =IF(E4="C",1,0) -> 1 | L4: 4
A5: MINA CANDELARIA | B5: FEBRERO | C5: 2 | D5: IPERC | E5: ='CUMPLIMIENTO GUARDIAS'!J5 -> C | F5: ='CUMPLIMIENTO GUARDIAS'!I5 -> 1 | G5: ='CUMPLIMIENTO GUARDIAS'!E5 -> C | H5: ='CUMPLIMIENTO GUARDIAS'!F5 -> C | I5: ='CUMPLIMIENTO GUARDIAS'!G5 -> C | J5: =--(C5<=MATCH('DASHBOARD AVANZADO'!$G$3,'DASHBOARD AVANZADO'!$Q$1:$Q$12,0)) -> 1 | K5: =IF(E5="C",1,0) -> 1 | L5: 5
A6: MINA CANDELARIA | B6: MARZO | C6: 3 | D6: Trabajos en Altura | E6: ='CUMPLIMIENTO GUARDIAS'!J6 -> C | F6: ='CUMPLIMIENTO GUARDIAS'!I6 -> 1 | G6: ='CUMPLIMIENTO GUARDIAS'!E6 -> C | H6: ='CUMPLIMIENTO GUARDIAS'!F6 -> C | I6: ='CUMPLIMIENTO GUARDIAS'!G6 -> C | J6: =--(C6<=MATCH('DASHBOARD AVANZADO'!$G$3,'DASHBOARD AVANZADO'!$Q$1:$Q$12,0)) -> 1 | K6: =IF(E6="C",1,0) -> 1 | L6: 6
A7: MINA CANDELARIA | B7: MARZO | C7: 3 | D7: Prevención y Protección Contra Incendio | E7: ='CUMPLIMIENTO GUARDIAS'!J7 -> C | F7: ='CUMPLIMIENTO GUARDIAS'!I7 -> 1 | G7: ='CUMPLIMIENTO GUARDIAS'!E7 -> C | H7: ='CUMPLIMIENTO GUARDIAS'!F7 -> C | I7: ='CUMPLIMIENTO GUARDIAS'!G7 -> C | J7: =--(C7<=MATCH('DASHBOARD AVANZADO'!$G$3,'DASHBOARD AVANZADO'!$Q$1:$Q$12,0)) -> 1 | K7: =IF(E7="C",1,0) -> 1 | L7: 7
A8: MINA CANDELARIA | B8: ABRIL | C8: 4 | D8: Gestión de la Seguridad y Salud Ocupacional basado en el Reglamento de Seguridad y Salud Ocupacional, Política de Seguridad, Salud Ocupacional y Medio Ambiente. | E8: ='CUMPLIMIENTO GUARDIAS'!J8 -> C | F8: ='CUMPLIMIENTO GUARDIAS'!I8 -> 1 | G8: ='CUMPLIMIENTO GUARDIAS'!E8 -> C | H8: ='CUMPLIMIENTO GUARDIAS'!F8 -> C | I8: ='CUMPLIMIENTO GUARDIAS'!G8 -> C | J8: =--(C8<=MATCH('DASHBOARD AVANZADO'!$G$3,'DASHBOARD AVANZADO'!$Q$1:$Q$12,0)) -> 1 | K8: =IF(E8="C",1,0) -> 1 | L8: 8
A9: MINA CANDELARIA | B9: ABRIL | C9: 4 | D9: Mapa de riesgos | E9: ='CUMPLIMIENTO GUARDIAS'!J9 -> C | F9: ='CUMPLIMIENTO GUARDIAS'!I9 -> 1 | G9: ='CUMPLIMIENTO GUARDIAS'!E9 -> C | H9: ='CUMPLIMIENTO GUARDIAS'!F9 -> C | I9: ='CUMPLIMIENTO GUARDIAS'!G9 -> C | J9: =--(C9<=MATCH('DASHBOARD AVANZADO'!$G$3,'DASHBOARD AVANZADO'!$Q$1:$Q$12,0)) -> 1 | K9: =IF(E9="C",1,0) -> 1 | L9: 9
A10: MINA CANDELARIA | B10: ABRIL | C10: 4 | D10: Estándares y procedimiento escrito de trabajo seguro por actividades | E10: ='CUMPLIMIENTO GUARDIAS'!J10 -> C | F10: ='CUMPLIMIENTO GUARDIAS'!I10 -> 1 | G10: ='CUMPLIMIENTO GUARDIAS'!E10 -> C | H10: ='CUMPLIMIENTO GUARDIAS'!F10 -> C | I10: ='CUMPLIMIENTO GUARDIAS'!G10 -> C | J10: =--(C10<=MATCH('DASHBOARD AVANZADO'!$G$3,'DASHBOARD AVANZADO'!$Q$1:$Q$12,0)) -> 1 | K10: =IF(E10="C",1,0) -> 1 | L10: 10
A11: MINA CANDELARIA | B11: MAYO | C11: 5 | D11: Significado y uso de código de señales y colores. | E11: ='CUMPLIMIENTO GUARDIAS'!J11 -> C | F11: ='CUMPLIMIENTO GUARDIAS'!I11 -> 1 | G11: ='CUMPLIMIENTO GUARDIAS'!E11 -> C | H11: ='CUMPLIMIENTO GUARDIAS'!F11 -> C | I11: ='CUMPLIMIENTO GUARDIAS'!G11 -> C | J11: =--(C11<=MATCH('DASHBOARD AVANZADO'!$G$3,'DASHBOARD AVANZADO'!$Q$1:$Q$12,0)) -> 1 | K11: =IF(E11="C",1,0) -> 1 | L11: 11
A12: MINA CANDELARIA | B12: MAYO | C12: 5 | D12: Auditoría, fiscalización e Inspecciones de Seguridad | E12: ='CUMPLIMIENTO GUARDIAS'!J12 -> C | F12: ='CUMPLIMIENTO GUARDIAS'!I12 -> 1 | G12: ='CUMPLIMIENTO GUARDIAS'!E12 -> C | H12: ='CUMPLIMIENTO GUARDIAS'!F12 -> C | I12: ='CUMPLIMIENTO GUARDIAS'!G12 -> C | J12: =--(C12<=MATCH('DASHBOARD AVANZADO'!$G$3,'DASHBOARD AVANZADO'!$Q$1:$Q$12,0)) -> 1 | K12: =IF(E12="C",1,0) -> 1 | L12: 12
A13: MINA CANDELARIA | B13: JUNIO | C13: 6 | D13: IPERC | E13: ='CUMPLIMIENTO GUARDIAS'!J13 -> C | F13: ='CUMPLIMIENTO GUARDIAS'!I13 -> 1 | G13: ='CUMPLIMIENTO GUARDIAS'!E13 -> C | H13: ='CUMPLIMIENTO GUARDIAS'!F13 -> C | I13: ='CUMPLIMIENTO GUARDIAS'!G13 -> C | J13: =--(C13<=MATCH('DASHBOARD AVANZADO'!$G$3,'DASHBOARD AVANZADO'!$Q$1:$Q$12,0)) -> 1 | K13: =IF(E13="C",1,0) -> 1 | L13: 13
... A406: CONGEMIN | B406: DICIEMBRE | C406: 12 | D406: Respuesta a Emergencias por Áreas específicas. | E406: ='CUMPLIMIENTO GUARDIAS'!J406 -> 0 | F406: ='CUMPLIMIENTO GUARDIAS'!I406 -> 0 | G406: ='CUMPLIMIENTO GUARDIAS'!E406 -> 0 | H406: ='CUMPLIMIENTO GUARDIAS'!F406 -> 0 | I406: ='CUMPLIMIENTO GUARDIAS'!G406 -> 0 | J406: =--(C406<=MATCH('DASHBOARD AVANZADO'!$G$3,'DASHBOARD AVANZADO'!$Q$1:$Q$12,0)) -> 0 | K406: =IF(E406="C",1,0) -> 0 | L406: 406

Sheet DASHBOARD AVANZADO
A1: DASHBOARD AVANZADO – CAPACITACIONES ANEXO 6 | P1: MINA CANDELARIA | Q1: ENERO | R1: Estado | S1: Cantidad
P2: PLANTA MAHUARA | Q2: FEBRERO | R2: Cumplidas | S2: =C7 -> 14
A3: Área seleccionada | B3: MINA CANDELARIA | F3: Mes de corte | G3: JULIO | J3: Códigos | K3: C = Cumplida | F = Falta | EP = En proceso | P3: ADMINISTRACIÓN | Q3: MARZO | R3: Faltantes | S3: =E7 -> 2
P4: MANTENIMIENTO | Q4: ABRIL | R4: En proceso | S4: =G7 -> 1
P5: DESARROLLOS MINEROS | Q5: MAYO
A6: Temas programados | C6: Cumplidas | E6: Faltantes | G6: En proceso | I6: Cumplimiento al corte | P6: CAMPAMENTO | Q6: JUNIO
A7: =COUNTIFS('MAPEO TEMAS'!$A$2:$A$406,$B$3,'MAPEO TEMAS'!$C$2:$C$406,"<="&MATCH($G$3,$Q$1:$Q$12,0)) -> 17 | C7: =COUNTIFS('MAPEO TEMAS'!$A$2:$A$406,$B$3,'MAPEO TEMAS'!$C$2:$C$406,"<="&MATCH($G$3,$Q$1:$Q$12,0),'MAPEO TEMAS'!$E$2:$E$406,"C") -> 14 | E7: =COUNTIFS('MAPEO TEMAS'!$A$2:$A$406,$B$3,'MAPEO TEMAS'!$C$2:$C$406,"<="&MATCH($G$3,$Q$1:$Q$12,0),'MAPEO TEMAS'!$E$2:$E$406,"F") -> 2 | G7: =COUNTIFS('MAPEO TEMAS'!$A$2:$A$406,$B$3,'MAPEO TEMAS'!$C$2:$C$406,"<="&MATCH($G$3,$Q$1:$Q$12,0),'MAPEO TEMAS'!$E$2:$E$406,"EP") -> 1 | I7: =IFERROR(C7/A7,0) -> 0.82352941 | P7: COMEDOR | Q7: JULIO
P8: MEDIO AMBIENTE | Q8: AGOSTO
P9: GEOLOGÍA | Q9: SETIEMBRE
A10: Avance calendario | D10: Avance real anual | G10: Promedio guardias | J10: Brecha al corte | P10: LOGÍSTICA | Q10: OCTUBRE
A11: =A7/27 -> 0.62962963 | D11: =C7/27 -> 0.51851852 | G11: =IFERROR(AVERAGEIFS('MAPEO TEMAS'!$F$2:$F$406,'MAPEO TEMAS'!$A$2:$A$406,$B$3,'MAPEO TEMAS'!$C$2:$C$406,"<="&MATCH($G$3,$Q$1:$Q$12,0)),0) -> 0.82352941 | J11: =I7-1 -> -0.17647059 | P11: RENTACAR | Q11: NOVIEMBRE
P12: IRENE | Q12: DICIEMBRE
P13: OBRAS CIVILES
A14: TEMAS FALTANTES O EN PROCESO AL MES DE CORTE | J14: CUMPLIMIENTO POR GUARDIA | P14: DIAMANTINA
A15: Mes | B15: Tema | C15: Estado | D15: % Guardias | E15: Guardia A | F15: Guardia B | G15: Guardia C | H15: N° | J15: Guardia | K15: C | L15: F | M15: EP | N15: % Cumplimiento | P15: CONGEMIN
A16: =IF($H16="","",INDEX('MAPEO TEMAS'!$B$2:$B$406,$H16)) | B16: =IF($H16="","",INDEX('MAPEO TEMAS'!$D$2:$D$406,$H16)) | C16: =IF($H16="","",INDEX('MAPEO TEMAS'!$E$2:$E$406,$H16)) | D16: =IF($H16="","",INDEX('MAPEO TEMAS'!$F$2:$F$406,$H16)) | E16: =IF($H16="","",INDEX('MAPEO TEMAS'!$G$2:$G$406,$H16)) | F16: =IF($H16="","",INDEX('MAPEO TEMAS'!$H$2:$H$406,$H16)) | G16: =IF($H16="","",INDEX('MAPEO TEMAS'!$I$2:$I$406,$H16)) | H16: =IFERROR(_xludf.AGGREGATE(15,6,(ROW('MAPEO TEMAS'!$A$2:$A$406)-1)/(('MAPEO TEMAS'!$A$2:$A$406=$B$3)*('MAPEO TEMAS'!$C$2:$C$406<=MATCH($G$3,$Q$1:$Q$12,0))*(('MAPEO TEMAS'!$E$2:$E$406="F")+('MAPEO TEMAS'!$E$2:$E$406="EP"))),ROWS($H$16:H16)),"") | J16: Guardia A | K16: =COUNTIFS('MAPEO TEMAS'!$A$2:$A$406,$B$3,'MAPEO TEMAS'!$C$2:$C$406,"<="&MATCH($G$3,$Q$1:$Q$12,0),'MAPEO TEMAS'!$G$2:$G$406,"C") -> 14 | L16: =COUNTIFS('MAPEO TEMAS'!$A$2:$A$406,$B$3,'MAPEO TEMAS'!$C$2:$C$406,"<="&MATCH($G$3,$Q$1:$Q$12,0),'MAPEO TEMAS'!$G$2:$G$406,"F") -> 1 | M16: =COUNTIFS('MAPEO TEMAS'!$A$2:$A$406,$B$3,'MAPEO TEMAS'!$C$2:$C$406,"<="&MATCH($G$3,$Q$1:$Q$12,0),'MAPEO TEMAS'!$G$2:$G$406,"EP") -> 1 | N16: =IFERROR(K16/$A$7,0) -> 0.82352941
A17: =IF($H17="","",INDEX('MAPEO TEMAS'!$B$2:$B$406,$H17)) | B17: =IF($H17="","",INDEX('MAPEO TEMAS'!$D$2:$D$406,$H17)) | C17: =IF($H17="","",INDEX('MAPEO TEMAS'!$E$2:$E$406,$H17)) | D17: =IF($H17="","",INDEX('MAPEO TEMAS'!$F$2:$F$406,$H17)) | E17: =IF($H17="","",INDEX('MAPEO TEMAS'!$G$2:$G$406,$H17)) | F17: =IF($H17="","",INDEX('MAPEO TEMAS'!$H$2:$H$406,$H17)) | G17: =IF($H17="","",INDEX('MAPEO TEMAS'!$I$2:$I$406,$H17)) | H17: =IFERROR(_xludf.AGGREGATE(15,6,(ROW('MAPEO TEMAS'!$A$2:$A$406)-1)/(('MAPEO TEMAS'!$A$2:$A$406=$B$3)*('MAPEO TEMAS'!$C$2:$C$406<=MATCH($G$3,$Q$1:$Q$12,0))*(('MAPEO TEMAS'!$E$2:$E$406="F")+('MAPEO TEMAS'!$E$2:$E$406="EP"))),ROWS($H$16:H17)),"") | J17: Guardia B | K17: =COUNTIFS('MAPEO TEMAS'!$A$2:$A$406,$B$3,'MAPEO TEMAS'!$C$2:$C$406,"<="&MATCH($G$3,$Q$1:$Q$12,0),'MAPEO TEMAS'!$H$2:$H$406,"C") -> 14 | L17: =COUNTIFS('MAPEO TEMAS'!$A$2:$A$406,$B$3,'MAPEO TEMAS'!$C$2:$C$406,"<="&MATCH($G$3,$Q$1:$Q$12,0),'MAPEO TEMAS'!$H$2:$H$406,"F") -> 1 | M17: =COUNTIFS('MAPEO TEMAS'!$A$2:$A$406,$B$3,'MAPEO TEMAS'!$C$2:$C$406,"<="&MATCH($G$3,$Q$1:$Q$12,0),'MAPEO TEMAS'!$H$2:$H$406,"EP") -> 1 | N17: =IFERROR(K17/$A$7,0) -> 0.82352941
A18: =IF($H18="","",INDEX('MAPEO TEMAS'!$B$2:$B$406,$H18)) | B18: =IF($H18="","",INDEX('MAPEO TEMAS'!$D$2:$D$406,$H18)) | C18: =IF($H18="","",INDEX('MAPEO TEMAS'!$E$2:$E$406,$H18)) | D18: =IF($H18="","",INDEX('MAPEO TEMAS'!$F$2:$F$406,$H18)) | E18: =IF($H18="","",INDEX('MAPEO TEMAS'!$G$2:$G$406,$H18)) | F18: =IF($H18="","",INDEX('MAPEO TEMAS'!$H$2:$H$406,$H18)) | G18: =IF($H18="","",INDEX('MAPEO TEMAS'!$I$2:$I$406,$H18)) | H18: =IFERROR(_xludf.AGGREGATE(15,6,(ROW('MAPEO TEMAS'!$A$2:$A$406)-1)/(('MAPEO TEMAS'!$A$2:$A$406=$B$3)*('MAPEO TEMAS'!$C$2:$C$406<=MATCH($G$3,$Q$1:$Q$12,0))*(('MAPEO TEMAS'!$E$2:$E$406="F")+('MAPEO TEMAS'!$E$2:$E$406="EP"))),ROWS($H$16:H18)),"") | J18: Guardia C | K18: =COUNTIFS('MAPEO TEMAS'!$A$2:$A$406,$B$3,'MAPEO TEMAS'!$C$2:$C$406,"<="&MATCH($G$3,$Q$1:$Q$12,0),'MAPEO TEMAS'!$I$2:$I$406,"C") -> 14 | L18: =COUNTIFS('MAPEO TEMAS'!$A$2:$A$406,$B$3,'MAPEO TEMAS'!$C$2:$C$406,"<="&MATCH($G$3,$Q$1:$Q$12,0),'MAPEO TEMAS'!$I$2:$I$406,"F") -> 1 | M18: =COUNTIFS('MAPEO TEMAS'!$A$2:$A$406,$B$3,'MAPEO TEMAS'!$C$2:$C$406,"<="&MATCH($G$3,$Q$1:$Q$12,0),'MAPEO TEMAS'!$I$2:$I$406,"EP") -> 1 | N18: =IFERROR(K18/$A$7,0) -> 0.82352941
A19: =IF($H19="","",INDEX('MAPEO TEMAS'!$B$2:$B$406,$H19)) | B19: =IF($H19="","",INDEX('MAPEO TEMAS'!$D$2:$D$406,$H19)) | C19: =IF($H19="","",INDEX('MAPEO TEMAS'!$E$2:$E$406,$H19)) | D19: =IF($H19="","",INDEX('MAPEO TEMAS'!$F$2:$F$406,$H19)) | E19: =IF($H19="","",INDEX('MAPEO TEMAS'!$G$2:$G$406,$H19)) | F19: =IF($H19="","",INDEX('MAPEO TEMAS'!$H$2:$H$406,$H19)) | G19: =IF($H19="","",INDEX('MAPEO TEMAS'!$I$2:$I$406,$H19)) | H19: =IFERROR(_xludf.AGGREGATE(15,6,(ROW('MAPEO TEMAS'!$A$2:$A$406)-1)/(('MAPEO TEMAS'!$A$2:$A$406=$B$3)*('MAPEO TEMAS'!$C$2:$C$406<=MATCH($G$3,$Q$1:$Q$12,0))*(('MAPEO TEMAS'!$E$2:$E$406="F")+('MAPEO TEMAS'!$E$2:$E$406="EP"))),ROWS($H$16:H19)),"") | J19: Estado | K19: Cantidad
A20: =IF($H20="","",INDEX('MAPEO TEMAS'!$B$2:$B$406,$H20)) | B20: =IF($H20="","",INDEX('MAPEO TEMAS'!$D$2:$D$406,$H20)) | C20: =IF($H20="","",INDEX('MAPEO TEMAS'!$E$2:$E$406,$H20)) | D20: =IF($H20="","",INDEX('MAPEO TEMAS'!$F$2:$F$406,$H20)) | E20: =IF($H20="","",INDEX('MAPEO TEMAS'!$G$2:$G$406,$H20)) | F20: =IF($H20="","",INDEX('MAPEO TEMAS'!$H$2:$H$406,$H20)) | G20: =IF($H20="","",INDEX('MAPEO TEMAS'!$I$2:$I$406,$H20)) | H20: =IFERROR(_xludf.AGGREGATE(15,6,(ROW('MAPEO TEMAS'!$A$2:$A$406)-1)/(('MAPEO TEMAS'!$A$2:$A$406=$B$3)*('MAPEO TEMAS'!$C$2:$C$406<=MATCH($G$3,$Q$1:$Q$12,0))*(('MAPEO TEMAS'!$E$2:$E$406="F")+('MAPEO TEMAS'!$E$2:$E$406="EP"))),ROWS($H$16:H20)),"")
A21: =IF($H21="","",INDEX('MAPEO TEMAS'!$B$2:$B$406,$H21)) | B21: =IF($H21="","",INDEX('MAPEO TEMAS'!$D$2:$D$406,$H21)) | C21: =IF($H21="","",INDEX('MAPEO TEMAS'!$E$2:$E$406,$H21)) | D21: =IF($H21="","",INDEX('MAPEO TEMAS'!$F$2:$F$406,$H21)) | E21: =IF($H21="","",INDEX('MAPEO TEMAS'!$G$2:$G$406,$H21)) | F21: =IF($H21="","",INDEX('MAPEO TEMAS'!$H$2:$H$406,$H21)) | G21: =IF($H21="","",INDEX('MAPEO TEMAS'!$I$2:$I$406,$H21)) | H21: =IFERROR(_xludf.AGGREGATE(15,6,(ROW('MAPEO TEMAS'!$A$2:$A$406)-1)/(('MAPEO TEMAS'!$A$2:$A$406=$B$3)*('MAPEO TEMAS'!$C$2:$C$406<=MATCH($G$3,$Q$1:$Q$12,0))*(('MAPEO TEMAS'!$E$2:$E$406="F")+('MAPEO TEMAS'!$E$2:$E$406="EP"))),ROWS($H$16:H21)),"") | J21: CUMPLIMIENTO POR TEMA Y GUARDIA
A22: =IF($H22="","",INDEX('MAPEO TEMAS'!$B$2:$B$406,$H22)) | B22: =IF($H22="","",INDEX('MAPEO TEMAS'!$D$2:$D$406,$H22)) | C22: =IF($H22="","",INDEX('MAPEO TEMAS'!$E$2:$E$406,$H22)) | D22: =IF($H22="","",INDEX('MAPEO TEMAS'!$F$2:$F$406,$H22)) | E22: =IF($H22="","",INDEX('MAPEO TEMAS'!$G$2:$G$406,$H22)) | F22: =IF($H22="","",INDEX('MAPEO TEMAS'!$H$2:$H$406,$H22)) | G22: =IF($H22="","",INDEX('MAPEO TEMAS'!$I$2:$I$406,$H22)) | H22: =IFERROR(_xludf.AGGREGATE(15,6,(ROW('MAPEO TEMAS'!$A$2:$A$406)-1)/(('MAPEO TEMAS'!$A$2:$A$406=$B$3)*('MAPEO TEMAS'!$C$2:$C$406<=MATCH($G$3,$Q$1:$Q$12,0))*(('MAPEO TEMAS'!$E$2:$E$406="F")+('MAPEO TEMAS'!$E$2:$E$406="EP"))),ROWS($H$16:H22)),"") | J22: Tema | K22: Mes | L22: A | M22: B | N22: C
A23: =IF($H23="","",INDEX('MAPEO TEMAS'!$B$2:$B$406,$H23)) | B23: =IF($H23="","",INDEX('MAPEO TEMAS'!$D$2:$D$406,$H23)) | C23: =IF($H23="","",INDEX('MAPEO TEMAS'!$E$2:$E$406,$H23)) | D23: =IF($H23="","",INDEX('MAPEO TEMAS'!$F$2:$F$406,$H23)) | E23: =IF($H23="","",INDEX('MAPEO TEMAS'!$G$2:$G$406,$H23)) | F23: =IF($H23="","",INDEX('MAPEO TEMAS'!$H$2:$H$406,$H23)) | G23: =IF($H23="","",INDEX('MAPEO TEMAS'!$I$2:$I$406,$H23)) | H23: =IFERROR(_xludf.AGGREGATE(15,6,(ROW('MAPEO TEMAS'!$A$2:$A$406)-1)/(('MAPEO TEMAS'!$A$2:$A$406=$B$3)*('MAPEO TEMAS'!$C$2:$C$406<=MATCH($G$3,$Q$1:$Q$12,0))*(('MAPEO TEMAS'!$E$2:$E$406="F")+('MAPEO TEMAS'!$E$2:$E$406="EP"))),ROWS($H$16:H23)),"") | J23: =IF($O23="","",INDEX('MAPEO TEMAS'!$D$2:$D$406,$O23)) | K23: =IF($O23="","",INDEX('MAPEO TEMAS'!$B$2:$B$406,$O23)) | L23: =IF($O23="","",INDEX('MAPEO TEMAS'!$G$2:$G$406,$O23)) | M23: =IF($O23="","",INDEX('MAPEO TEMAS'!$H$2:$H$406,$O23)) | N23: =IF($O23="","",INDEX('MAPEO TEMAS'!$I$2:$I$406,$O23)) | O23: =IFERROR(_xludf.AGGREGATE(15,6,(ROW('MAPEO TEMAS'!$A$2:$A$406)-1)/(('MAPEO TEMAS'!$A$2:$A$406=$B$3)*('MAPEO TEMAS'!$C$2:$C$406<=MATCH($G$3,$Q$1:$Q$12,0))),ROWS($O$23:O23)),"")
A24: =IF($H24="","",INDEX('MAPEO TEMAS'!$B$2:$B$406,$H24)) | B24: =IF($H24="","",INDEX('MAPEO TEMAS'!$D$2:$D$406,$H24)) | C24: =IF($H24="","",INDEX('MAPEO TEMAS'!$E$2:$E$406,$H24)) | D24: =IF($H24="","",INDEX('MAPEO TEMAS'!$F$2:$F$406,$H24)) | E24: =IF($H24="","",INDEX('MAPEO TEMAS'!$G$2:$G$406,$H24)) | F24: =IF($H24="","",INDEX('MAPEO TEMAS'!$H$2:$H$406,$H24)) | G24: =IF($H24="","",INDEX('MAPEO TEMAS'!$I$2:$I$406,$H24)) | H24: =IFERROR(_xludf.AGGREGATE(15,6,(ROW('MAPEO TEMAS'!$A$2:$A$406)-1)/(('MAPEO TEMAS'!$A$2:$A$406=$B$3)*('MAPEO TEMAS'!$C$2:$C$406<=MATCH($G$3,$Q$1:$Q$12,0))*(('MAPEO TEMAS'!$E$2:$E$406="F")+('MAPEO TEMAS'!$E$2:$E$406="EP"))),ROWS($H$16:H24)),"") | J24: =IF($O24="","",INDEX('MAPEO TEMAS'!$D$2:$D$406,$O24)) | K24: =IF($O24="","",INDEX('MAPEO TEMAS'!$B$2:$B$406,$O24)) | L24: =IF($O24="","",INDEX('MAPEO TEMAS'!$G$2:$G$406,$O24)) | M24: =IF($O24="","",INDEX('MAPEO TEMAS'!$H$2:$H$406,$O24)) | N24: =IF($O24="","",INDEX('MAPEO TEMAS'!$I$2:$I$406,$O24)) | O24: =IFERROR(_xludf.AGGREGATE(15,6,(ROW('MAPEO TEMAS'!$A$2:$A$406)-1)/(('MAPEO TEMAS'!$A$2:$A$406=$B$3)*('MAPEO TEMAS'!$C$2:$C$406<=MATCH($G$3,$Q$1:$Q$12,0))),ROWS($O$23:O24)),"")
A25: =IF($H25="","",INDEX('MAPEO TEMAS'!$B$2:$B$406,$H25)) | B25: =IF($H25="","",INDEX('MAPEO TEMAS'!$D$2:$D$406,$H25)) | C25: =IF($H25="","",INDEX('MAPEO TEMAS'!$E$2:$E$406,$H25)) | D25: =IF($H25="","",INDEX('MAPEO TEMAS'!$F$2:$F$406,$H25)) | E25: =IF($H25="","",INDEX('MAPEO TEMAS'!$G$2:$G$406,$H25)) | F25: =IF($H25="","",INDEX('MAPEO TEMAS'!$H$2:$H$406,$H25)) | G25: =IF($H25="","",INDEX('MAPEO TEMAS'!$I$2:$I$406,$H25)) | H25: =IFERROR(_xludf.AGGREGATE(15,6,(ROW('MAPEO TEMAS'!$A$2:$A$406)-1)/(('MAPEO TEMAS'!$A$2:$A$406=$B$3)*('MAPEO TEMAS'!$C$2:$C$406<=MATCH($G$3,$Q$1:$Q$12,0))*(('MAPEO TEMAS'!$E$2:$E$406="F")+('MAPEO TEMAS'!$E$2:$E$406="EP"))),ROWS($H$16:H25)),"") | J25: =IF($O25="","",INDEX('MAPEO TEMAS'!$D$2:$D$406,$O25)) | K25: =IF($O25="","",INDEX('MAPEO TEMAS'!$B$2:$B$406,$O25)) | L25: =IF($O25="","",INDEX('MAPEO TEMAS'!$G$2:$G$406,$O25)) | M25: =IF($O25="","",INDEX('MAPEO TEMAS'!$H$2:$H$406,$O25)) | N25: =IF($O25="","",INDEX('MAPEO TEMAS'!$I$2:$I$406,$O25)) | O25: =IFERROR(_xludf.AGGREGATE(15,6,(ROW('MAPEO TEMAS'!$A$2:$A$406)-1)/(('MAPEO TEMAS'!$A$2:$A$406=$B$3)*('MAPEO TEMAS'!$C$2:$C$406<=MATCH($G$3,$Q$1:$Q$12,0))),ROWS($O$23:O25)),"")
A26: =IF($H26="","",INDEX('MAPEO TEMAS'!$B$2:$B$406,$H26)) | B26: =IF($H26="","",INDEX('MAPEO TEMAS'!$D$2:$D$406,$H26)) | C26: =IF($H26="","",INDEX('MAPEO TEMAS'!$E$2:$E$406,$H26)) | D26: =IF($H26="","",INDEX('MAPEO TEMAS'!$F$2:$F$406,$H26)) | E26: =IF($H26="","",INDEX('MAPEO TEMAS'!$G$2:$G$406,$H26)) | F26: =IF($H26="","",INDEX('MAPEO TEMAS'!$H$2:$H$406,$H26)) | G26: =IF($H26="","",INDEX('MAPEO TEMAS'!$I$2:$I$406,$H26)) | H26: =IFERROR(_xludf.AGGREGATE(15,6,(ROW('MAPEO TEMAS'!$A$2:$A$406)-1)/(('MAPEO TEMAS'!$A$2:$A$406=$B$3)*('MAPEO TEMAS'!$C$2:$C$406<=MATCH($G$3,$Q$1:$Q$12,0))*(('MAPEO TEMAS'!$E$2:$E$406="F")+('MAPEO TEMAS'!$E$2:$E$406="EP"))),ROWS($H$16:H26)),"") | J26: =IF($O26="","",INDEX('MAPEO TEMAS'!$D$2:$D$406,$O26)) | K26: =IF($O26="","",INDEX('MAPEO TEMAS'!$B$2:$B$406,$O26)) | L26: =IF($O26="","",INDEX('MAPEO TEMAS'!$G$2:$G$406,$O26)) | M26: =IF($O26="","",INDEX('MAPEO TEMAS'!$H$2:$H$406,$O26)) | N26: =IF($O26="","",INDEX('MAPEO TEMAS'!$I$2:$I$406,$O26)) | O26: =IFERROR(_xludf.AGGREGATE(15,6,(ROW('MAPEO TEMAS'!$A$2:$A$406)-1)/(('MAPEO TEMAS'!$A$2:$A$406=$B$3)*('MAPEO TEMAS'!$C$2:$C$406<=MATCH($G$3,$Q$1:$Q$12,0))),ROWS($O$23:O26)),"")
A27: =IF($H27="","",INDEX('MAPEO TEMAS'!$B$2:$B$406,$H27)) | B27: =IF($H27="","",INDEX('MAPEO TEMAS'!$D$2:$D$406,$H27)) | C27: =IF($H27="","",INDEX('MAPEO TEMAS'!$E$2:$E$406,$H27)) | D27: =IF($H27="","",INDEX('MAPEO TEMAS'!$F$2:$F$406,$H27)) | E27: =IF($H27="","",INDEX('MAPEO TEMAS'!$G$2:$G$406,$H27)) | F27: =IF($H27="","",INDEX('MAPEO TEMAS'!$H$2:$H$406,$H27)) | G27: =IF($H27="","",INDEX('MAPEO TEMAS'!$I$2:$I$406,$H27)) | H27: =IFERROR(_xludf.AGGREGATE(15,6,(ROW('MAPEO TEMAS'!$A$2:$A$406)-1)/(('MAPEO TEMAS'!$A$2:$A$406=$B$3)*('MAPEO TEMAS'!$C$2:$C$406<=MATCH($G$3,$Q$1:$Q$12,0))*(('MAPEO TEMAS'!$E$2:$E$406="F")+('MAPEO TEMAS'!$E$2:$E$406="EP"))),ROWS($H$16:H27)),"") | J27: =IF($O27="","",INDEX('MAPEO TEMAS'!$D$2:$D$406,$O27)) | K27: =IF($O27="","",INDEX('MAPEO TEMAS'!$B$2:$B$406,$O27)) | L27: =IF($O27="","",INDEX('MAPEO TEMAS'!$G$2:$G$406,$O27)) | M27: =IF($O27="","",INDEX('MAPEO TEMAS'!$H$2:$H$406,$O27)) | N27: =IF($O27="","",INDEX('MAPEO TEMAS'!$I$2:$I$406,$O27)) | O27: =IFERROR(_xludf.AGGREGATE(15,6,(ROW('MAPEO TEMAS'!$A$2:$A$406)-1)/(('MAPEO TEMAS'!$A$2:$A$406=$B$3)*('MAPEO TEMAS'!$C$2:$C$406<=MATCH($G$3,$Q$1:$Q$12,0))),ROWS($O$23:O27)),"")
A28: =IF($H28="","",INDEX('MAPEO TEMAS'!$B$2:$B$406,$H28)) | B28: =IF($H28="","",INDEX('MAPEO TEMAS'!$D$2:$D$406,$H28)) | C28: =IF($H28="","",INDEX('MAPEO TEMAS'!$E$2:$E$406,$H28)) | D28: =IF($H28="","",INDEX('MAPEO TEMAS'!$F$2:$F$406,$H28)) | E28: =IF($H28="","",INDEX('MAPEO TEMAS'!$G$2:$G$406,$H28)) | F28: =IF($H28="","",INDEX('MAPEO TEMAS'!$H$2:$H$406,$H28)) | G28: =IF($H28="","",INDEX('MAPEO TEMAS'!$I$2:$I$406,$H28)) | H28: =IFERROR(_xludf.AGGREGATE(15,6,(ROW('MAPEO TEMAS'!$A$2:$A$406)-1)/(('MAPEO TEMAS'!$A$2:$A$406=$B$3)*('MAPEO TEMAS'!$C$2:$C$406<=MATCH($G$3,$Q$1:$Q$12,0))*(('MAPEO TEMAS'!$E$2:$E$406="F")+('MAPEO TEMAS'!$E$2:$E$406="EP"))),ROWS($H$16:H28)),"") | J28: =IF($O28="","",INDEX('MAPEO TEMAS'!$D$2:$D$406,$O28)) | K28: =IF($O28="","",INDEX('MAPEO TEMAS'!$B$2:$B$406,$O28)) | L28: =IF($O28="","",INDEX('MAPEO TEMAS'!$G$2:$G$406,$O28)) | M28: =IF($O28="","",INDEX('MAPEO TEMAS'!$H$2:$H$406,$O28)) | N28: =IF($O28="","",INDEX('MAPEO TEMAS'!$I$2:$I$406,$O28)) | O28: =IFERROR(_xludf.AGGREGATE(15,6,(ROW('MAPEO TEMAS'!$A$2:$A$406)-1)/(('MAPEO TEMAS'!$A$2:$A$406=$B$3)*('MAPEO TEMAS'!$C$2:$C$406<=MATCH($G$3,$Q$1:$Q$12,0))),ROWS($O$23:O28)),"")
A29: =IF($H29="","",INDEX('MAPEO TEMAS'!$B$2:$B$406,$H29)) | B29: =IF($H29="","",INDEX('MAPEO TEMAS'!$D$2:$D$406,$H29)) | C29: =IF($H29="","",INDEX('MAPEO TEMAS'!$E$2:$E$406,$H29)) | D29: =IF($H29="","",INDEX('MAPEO TEMAS'!$F$2:$F$406,$H29)) | E29: =IF($H29="","",INDEX('MAPEO TEMAS'!$G$2:$G$406,$H29)) | F29: =IF($H29="","",INDEX('MAPEO TEMAS'!$H$2:$H$406,$H29)) | G29: =IF($H29="","",INDEX('MAPEO TEMAS'!$I$2:$I$406,$H29)) | H29: =IFERROR(_xludf.AGGREGATE(15,6,(ROW('MAPEO TEMAS'!$A$2:$A$406)-1)/(('MAPEO TEMAS'!$A$2:$A$406=$B$3)*('MAPEO TEMAS'!$C$2:$C$406<=MATCH($G$3,$Q$1:$Q$12,0))*(('MAPEO TEMAS'!$E$2:$E$406="F")+('MAPEO TEMAS'!$E$2:$E$406="EP"))),ROWS($H$16:H29)),"") | J29: =IF($O29="","",INDEX('MAPEO TEMAS'!$D$2:$D$406,$O29)) | K29: =IF($O29="","",INDEX('MAPEO TEMAS'!$B$2:$B$406,$O29)) | L29: =IF($O29="","",INDEX('MAPEO TEMAS'!$G$2:$G$406,$O29)) | M29: =IF($O29="","",INDEX('MAPEO TEMAS'!$H$2:$H$406,$O29)) | N29: =IF($O29="","",INDEX('MAPEO TEMAS'!$I$2:$I$406,$O29)) | O29: =IFERROR(_xludf.AGGREGATE(15,6,(ROW('MAPEO TEMAS'!$A$2:$A$406)-1)/(('MAPEO TEMAS'!$A$2:$A$406=$B$3)*('MAPEO TEMAS'!$C$2:$C$406<=MATCH($G$3,$Q$1:$Q$12,0))),ROWS($O$23:O29)),"")
A30: =IF($H30="","",INDEX('MAPEO TEMAS'!$B$2:$B$406,$H30)) | B30: =IF($H30="","",INDEX('MAPEO TEMAS'!$D$2:$D$406,$H30)) | C30: =IF($H30="","",INDEX('MAPEO TEMAS'!$E$2:$E$406,$H30)) | D30: =IF($H30="","",INDEX('MAPEO TEMAS'!$F$2:$F$406,$H30)) | E30: =IF($H30="","",INDEX('MAPEO TEMAS'!$G$2:$G$406,$H30)) | F30: =IF($H30="","",INDEX('MAPEO TEMAS'!$H$2:$H$406,$H30)) | G30: =IF($H30="","",INDEX('MAPEO TEMAS'!$I$2:$I$406,$H30)) | H30: =IFERROR(_xludf.AGGREGATE(15,6,(ROW('MAPEO TEMAS'!$A$2:$A$406)-1)/(('MAPEO TEMAS'!$A$2:$A$406=$B$3)*('MAPEO TEMAS'!$C$2:$C$406<=MATCH($G$3,$Q$1:$Q$12,0))*(('MAPEO TEMAS'!$E$2:$E$406="F")+('MAPEO TEMAS'!$E$2:$E$406="EP"))),ROWS($H$16:H30)),"") | J30: =IF($O30="","",INDEX('MAPEO TEMAS'!$D$2:$D$406,$O30)) | K30: =IF($O30="","",INDEX('MAPEO TEMAS'!$B$2:$B$406,$O30)) | L30: =IF($O30="","",INDEX('MAPEO TEMAS'!$G$2:$G$406,$O30)) | M30: =IF($O30="","",INDEX('MAPEO TEMAS'!$H$2:$H$406,$O30)) | N30: =IF($O30="","",INDEX('MAPEO TEMAS'!$I$2:$I$406,$O30)) | O30: =IFERROR(_xludf.AGGREGATE(15,6,(ROW('MAPEO TEMAS'!$A$2:$A$406)-1)/(('MAPEO TEMAS'!$A$2:$A$406=$B$3)*('MAPEO TEMAS'!$C$2:$C$406<=MATCH($G$3,$Q$1:$Q$12,0))),ROWS($O$23:O30)),"")
A31: =IF($H31="","",INDEX('MAPEO TEMAS'!$B$2:$B$406,$H31)) | B31: =IF($H31="","",INDEX('MAPEO TEMAS'!$D$2:$D$406,$H31)) | C31: =IF($H31="","",INDEX('MAPEO TEMAS'!$E$2:$E$406,$H31)) | D31: =IF($H31="","",INDEX('MAPEO TEMAS'!$F$2:$F$406,$H31)) | E31: =IF($H31="","",INDEX('MAPEO TEMAS'!$G$2:$G$406,$H31)) | F31: =IF($H31="","",INDEX('MAPEO TEMAS'!$H$2:$H$406,$H31)) | G31: =IF($H31="","",INDEX('MAPEO TEMAS'!$I$2:$I$406,$H31)) | H31: =IFERROR(_xludf.AGGREGATE(15,6,(ROW('MAPEO TEMAS'!$A$2:$A$406)-1)/(('MAPEO TEMAS'!$A$2:$A$406=$B$3)*('MAPEO TEMAS'!$C$2:$C$406<=MATCH($G$3,$Q$1:$Q$12,0))*(('MAPEO TEMAS'!$E$2:$E$406="F")+('MAPEO TEMAS'!$E$2:$E$406="EP"))),ROWS($H$16:H31)),"") | J31: =IF($O31="","",INDEX('MAPEO TEMAS'!$D$2:$D$406,$O31)) | K31: =IF($O31="","",INDEX('MAPEO TEMAS'!$B$2:$B$406,$O31)) | L31: =IF($O31="","",INDEX('MAPEO TEMAS'!$G$2:$G$406,$O31)) | M31: =IF($O31="","",INDEX('MAPEO TEMAS'!$H$2:$H$406,$O31)) | N31: =IF($O31="","",INDEX('MAPEO TEMAS'!$I$2:$I$406,$O31)) | O31: =IFERROR(_xludf.AGGREGATE(15,6,(ROW('MAPEO TEMAS'!$A$2:$A$406)-1)/(('MAPEO TEMAS'!$A$2:$A$406=$B$3)*('MAPEO TEMAS'!$C$2:$C$406<=MATCH($G$3,$Q$1:$Q$12,0))),ROWS($O$23:O31)),"")
A32: =IF($H32="","",INDEX('MAPEO TEMAS'!$B$2:$B$406,$H32)) | B32: =IF($H32="","",INDEX('MAPEO TEMAS'!$D$2:$D$406,$H32)) | C32: =IF($H32="","",INDEX('MAPEO TEMAS'!$E$2:$E$406,$H32)) | D32: =IF($H32="","",INDEX('MAPEO TEMAS'!$F$2:$F$406,$H32)) | E32: =IF($H32="","",INDEX('MAPEO TEMAS'!$G$2:$G$406,$H32)) | F32: =IF($H32="","",INDEX('MAPEO TEMAS'!$H$2:$H$406,$H32)) | G32: =IF($H32="","",INDEX('MAPEO TEMAS'!$I$2:$I$406,$H32)) | H32: =IFERROR(_xludf.AGGREGATE(15,6,(ROW('MAPEO TEMAS'!$A$2:$A$406)-1)/(('MAPEO TEMAS'!$A$2:$A$406=$B$3)*('MAPEO TEMAS'!$C$2:$C$406<=MATCH($G$3,$Q$1:$Q$12,0))*(('MAPEO TEMAS'!$E$2:$E$406="F")+('MAPEO TEMAS'!$E$2:$E$406="EP"))),ROWS($H$16:H32)),"") | J32: =IF($O32="","",INDEX('MAPEO TEMAS'!$D$2:$D$406,$O32)) | K32: =IF($O32="","",INDEX('MAPEO TEMAS'!$B$2:$B$406,$O32)) | L32: =IF($O32="","",INDEX('MAPEO TEMAS'!$G$2:$G$406,$O32)) | M32: =IF($O32="","",INDEX('MAPEO TEMAS'!$H$2:$H$406,$O32)) | N32: =IF($O32="","",INDEX('MAPEO TEMAS'!$I$2:$I$406,$O32)) | O32: =IFERROR(_xludf.AGGREGATE(15,6,(ROW('MAPEO TEMAS'!$A$2:$A$406)-1)/(('MAPEO TEMAS'!$A$2:$A$406=$B$3)*('MAPEO TEMAS'!$C$2:$C$406<=MATCH($G$3,$Q$1:$Q$12,0))),ROWS($O$23:O32)),"")
A33: =IF($H33="","",INDEX('MAPEO TEMAS'!$B$2:$B$406,$H33)) | B33: =IF($H33="","",INDEX('MAPEO TEMAS'!$D$2:$D$406,$H33)) | C33: =IF($H33="","",INDEX('MAPEO TEMAS'!$E$2:$E$406,$H33)) | D33: =IF($H33="","",INDEX('MAPEO TEMAS'!$F$2:$F$406,$H33)) | E33: =IF($H33="","",INDEX('MAPEO TEMAS'!$G$2:$G$406,$H33)) | F33: =IF($H33="","",INDEX('MAPEO TEMAS'!$H$2:$H$406,$H33)) | G33: =IF($H33="","",INDEX('MAPEO TEMAS'!$I$2:$I$406,$H33)) | H33: =IFERROR(_xludf.AGGREGATE(15,6,(ROW('MAPEO TEMAS'!$A$2:$A$406)-1)/(('MAPEO TEMAS'!$A$2:$A$406=$B$3)*('MAPEO TEMAS'!$C$2:$C$406<=MATCH($G$3,$Q$1:$Q$12,0))*(('MAPEO TEMAS'!$E$2:$E$406="F")+('MAPEO TEMAS'!$E$2:$E$406="EP"))),ROWS($H$16:H33)),"") | J33: =IF($O33="","",INDEX('MAPEO TEMAS'!$D$2:$D$406,$O33)) | K33: =IF($O33="","",INDEX('MAPEO TEMAS'!$B$2:$B$406,$O33)) | L33: =IF($O33="","",INDEX('MAPEO TEMAS'!$G$2:$G$406,$O33)) | M33: =IF($O33="","",INDEX('MAPEO TEMAS'!$H$2:$H$406,$O33)) | N33: =IF($O33="","",INDEX('MAPEO TEMAS'!$I$2:$I$406,$O33)) | O33: =IFERROR(_xludf.AGGREGATE(15,6,(ROW('MAPEO TEMAS'!$A$2:$A$406)-1)/(('MAPEO TEMAS'!$A$2:$A$406=$B$3)*('MAPEO TEMAS'!$C$2:$C$406<=MATCH($G$3,$Q$1:$Q$12,0))),ROWS($O$23:O33)),"")
A34: =IF($H34="","",INDEX('MAPEO TEMAS'!$B$2:$B$406,$H34)) | B34: =IF($H34="","",INDEX('MAPEO TEMAS'!$D$2:$D$406,$H34)) | C34: =IF($H34="","",INDEX('MAPEO TEMAS'!$E$2:$E$406,$H34)) | D34: =IF($H34="","",INDEX('MAPEO TEMAS'!$F$2:$F$406,$H34)) | E34: =IF($H34="","",INDEX('MAPEO TEMAS'!$G$2:$G$406,$H34)) | F34: =IF($H34="","",INDEX('MAPEO TEMAS'!$H$2:$H$406,$H34)) | G34: =IF($H34="","",INDEX('MAPEO TEMAS'!$I$2:$I$406,$H34)) | H34: =IFERROR(_xludf.AGGREGATE(15,6,(ROW('MAPEO TEMAS'!$A$2:$A$406)-1)/(('MAPEO TEMAS'!$A$2:$A$406=$B$3)*('MAPEO TEMAS'!$C$2:$C$406<=MATCH($G$3,$Q$1:$Q$12,0))*(('MAPEO TEMAS'!$E$2:$E$406="F")+('MAPEO TEMAS'!$E$2:$E$406="EP"))),ROWS($H$16:H34)),"") | J34: =IF($O34="","",INDEX('MAPEO TEMAS'!$D$2:$D$406,$O34)) | K34: =IF($O34="","",INDEX('MAPEO TEMAS'!$B$2:$B$406,$O34)) | L34: =IF($O34="","",INDEX('MAPEO TEMAS'!$G$2:$G$406,$O34)) | M34: =IF($O34="","",INDEX('MAPEO TEMAS'!$H$2:$H$406,$O34)) | N34: =IF($O34="","",INDEX('MAPEO TEMAS'!$I$2:$I$406,$O34)) | O34: =IFERROR(_xludf.AGGREGATE(15,6,(ROW('MAPEO TEMAS'!$A$2:$A$406)-1)/(('MAPEO TEMAS'!$A$2:$A$406=$B$3)*('MAPEO TEMAS'!$C$2:$C$406<=MATCH($G$3,$Q$1:$Q$12,0))),ROWS($O$23:O34)),"")
... A45: =IF($H45="","",INDEX('MAPEO TEMAS'!$B$2:$B$406,$H45)) | B45: =IF($H45="","",INDEX('MAPEO TEMAS'!$D$2:$D$406,$H45)) | C45: =IF($H45="","",INDEX('MAPEO TEMAS'!$E$2:$E$406,$H45)) | D45: =IF($H45="","",INDEX('MAPEO TEMAS'!$F$2:$F$406,$H45)) | E45: =IF($H45="","",INDEX('MAPEO TEMAS'!$G$2:$G$406,$H45)) | F45: =IF($H45="","",INDEX('MAPEO TEMAS'!$H$2:$H$406,$H45)) | G45: =IF($H45="","",INDEX('MAPEO TEMAS'!$I$2:$I$406,$H45)) | H45: =IFERROR(_xludf.AGGREGATE(15,6,(ROW('MAPEO TEMAS'!$A$2:$A$406)-1)/(('MAPEO TEMAS'!$A$2:$A$406=$B$3)*('MAPEO TEMAS'!$C$2:$C$406<=MATCH($G$3,$Q$1:$Q$12,0))*(('MAPEO TEMAS'!$E$2:$E$406="F")+('MAPEO TEMAS'!$E$2:$E$406="EP"))),ROWS($H$16:H45)),"") | J45: =IF($O45="","",INDEX('MAPEO TEMAS'!$D$2:$D$406,$O45)) | K45: =IF($O45="","",INDEX('MAPEO TEMAS'!$B$2:$B$406,$O45)) | L45: =IF($O45="","",INDEX('MAPEO TEMAS'!$G$2:$G$406,$O45)) | M45: =IF($O45="","",INDEX('MAPEO TEMAS'!$H$2:$H$406,$O45)) | N45: =IF($O45="","",INDEX('MAPEO TEMAS'!$I$2:$I$406,$O45)) | O45: =IFERROR(_xludf.AGGREGATE(15,6,(ROW('MAPEO TEMAS'!$A$2:$A$406)-1)/(('MAPEO TEMAS'!$A$2:$A$406=$B$3)*('MAPEO TEMAS'!$C$2:$C$406<=MATCH($G$3,$Q$1:$Q$12,0))),ROWS($O$23:O45)),"")
J46: =IF($O46="","",INDEX('MAPEO TEMAS'!$D$2:$D$406,$O46)) | K46: =IF($O46="","",INDEX('MAPEO TEMAS'!$B$2:$B$406,$O46)) | L46: =IF($O46="","",INDEX('MAPEO TEMAS'!$G$2:$G$406,$O46)) | M46: =IF($O46="","",INDEX('MAPEO TEMAS'!$H$2:$H$406,$O46)) | N46: =IF($O46="","",INDEX('MAPEO TEMAS'!$I$2:$I$406,$O46)) | O46: =IFERROR(_xludf.AGGREGATE(15,6,(ROW('MAPEO TEMAS'!$A$2:$A$406)-1)/(('MAPEO TEMAS'!$A$2:$A$406=$B$3)*('MAPEO TEMAS'!$C$2:$C$406<=MATCH($G$3,$Q$1:$Q$12,0))),ROWS($O$23:O46)),"")
J47: =IF($O47="","",INDEX('MAPEO TEMAS'!$D$2:$D$406,$O47)) | K47: =IF($O47="","",INDEX('MAPEO TEMAS'!$B$2:$B$406,$O47)) | L47: =IF($O47="","",INDEX('MAPEO TEMAS'!$G$2:$G$406,$O47)) | M47: =IF($O47="","",INDEX('MAPEO TEMAS'!$H$2:$H$406,$O47)) | N47: =IF($O47="","",INDEX('MAPEO TEMAS'!$I$2:$I$406,$O47)) | O47: =IFERROR(_xludf.AGGREGATE(15,6,(ROW('MAPEO TEMAS'!$A$2:$A$406)-1)/(('MAPEO TEMAS'!$A$2:$A$406=$B$3)*('MAPEO TEMAS'!$C$2:$C$406<=MATCH($G$3,$Q$1:$Q$12,0))),ROWS($O$23:O47)),"")
J48: =IF($O48="","",INDEX('MAPEO TEMAS'!$D$2:$D$406,$O48)) | K48: =IF($O48="","",INDEX('MAPEO TEMAS'!$B$2:$B$406,$O48)) | L48: =IF($O48="","",INDEX('MAPEO TEMAS'!$G$2:$G$406,$O48)) | M48: =IF($O48="","",INDEX('MAPEO TEMAS'!$H$2:$H$406,$O48)) | N48: =IF($O48="","",INDEX('MAPEO TEMAS'!$I$2:$I$406,$O48)) | O48: =IFERROR(_xludf.AGGREGATE(15,6,(ROW('MAPEO TEMAS'!$A$2:$A$406)-1)/(('MAPEO TEMAS'!$A$2:$A$406=$B$3)*('MAPEO TEMAS'!$C$2:$C$406<=MATCH($G$3,$Q$1:$Q$12,0))),ROWS($O$23:O48)),"")
J49: =IF($O49="","",INDEX('MAPEO TEMAS'!$D$2:$D$406,$O49)) | K49: =IF($O49="","",INDEX('MAPEO TEMAS'!$B$2:$B$406,$O49)) | L49: =IF($O49="","",INDEX('MAPEO TEMAS'!$G$2:$G$406,$O49)) | M49: =IF($O49="","",INDEX('MAPEO TEMAS'!$H$2:$H$406,$O49)) | N49: =IF($O49="","",INDEX('MAPEO TEMAS'!$I$2:$I$406,$O49)) | O49: =IFERROR(_xludf.AGGREGATE(15,6,(ROW('MAPEO TEMAS'!$A$2:$A$406)-1)/(('MAPEO TEMAS'!$A$2:$A$406=$B$3)*('MAPEO TEMAS'!$C$2:$C$406<=MATCH($G$3,$Q$1:$Q$12,0))),ROWS($O$23:O49)),"")
